Workbook

Sheet Raccolta
O1: MIsura della temperatura ambiente: circa 1 ogni ora
B2: Ora | D2: Ora | F2: Ora | H2: Ora | J2: Ora | O2: 9:30 | P2: 10:30 | Q2: 11:30 | R2: 12:30
A3: Alluminio | C3: 1 | E3: 2 | G3: 3 | I3: 4 | K3: 5 | M3: * = temperatura ambiente | O3: 23 | P3: 24 | Q3: 24.4 | R3: 24.4
A4: T circa 65 °C | B4: 10:05 | C4: 70 | D4: 10:22 | E4: 64 | F4: 10:38 | G4: 65 | H4: 10:56 | I4: 66.8 | J4: 11:12 | K4: 69
A5: T1 | B5: 10:07 | C5: 66 | D5: 10:27 | E5: 62 | F5: 10:41 | G5: 61.2 | H5: 11:01 | I5: 63.8 | J5: 11:15 | K5: 65.2 | M5: NOTE
A6: m_a * | B6: 10:10 | C6: 202 | D6: 10:27 | E6: 201 | F6: 10:34 | G6: 203 | H6: 10:53 | I6: 202.5 | J6: 11:09 | K6: 202 | M6: - Aumento della accurrateza delle misure aumentando il tempo di immersione del campione in acqua a temperatura ambiente
A7: m1 | B7: 10:07 | C7: 79.5 | D7: 10:27 | E7: 79.5 | F7: 10:39 | G7: 79.5 | H7: 11:00 | I7: 79.5 | J7: 11:06 | K7: 79.5 | M7: - 3 misure del calore specifico dell'okite contro i 2 di ottone e granito. Scelata giustificata perché l'okite è l'unico materiale di cui non si può sapere a priori valore di c
A8: T_a | B8: 10:10 | C8: 20 | D8: 10:27 | E8: 23 | F8: 10:41 | G8: 20.6 | H8: 11:01 | I8: 23.2 | J8: 11:15 | K8: 24.2
A9: T_f | B9: 10:16 | C9: 23.2 | D9: 10:32 | E9: 25.6 | F9: 10:50 | G9: 23.4 | H9: 11:04 | I9: 26 | J9: 11:20 | K9: 27 | M9: COMPONENTI DEL GRUPPO
B10: Ora | D10: Ora | F10: Ora | H10: Ora | J10: Ora | M10: Caporuscio Gabriele
A11: Ottone | C11: 1 | E11: 2 | G11: 3 | I11: 4 (opzionale) | K11: 5 (opzionale) | M11: Comandini Cesare
A12: T circa 65 °C | B12: 11:22 | C12: 67 | D12: 13:01 | E12: 66 | M12: D'Agostino Niccolò
A13: T1 | B13: 11:25 | C13: 64 | D13: 13:01 | E13: 63.5 | M13: Di Noia Filippo
A14: m_a * | B14: 11:26 | C14: 200.6 | D14: 13:01 | E14: 202.4
A15: m1 | B15: 10:24 | C15: 195.3 | D15: 10:27 | E15: 195.3 | M15: Data e ora di inizio
A16: T_a | B16: 11:28 | C16: 20 | D16: 13:02 | E16: 21 | M16: 13/10/2026; 9:35/13:30
A17: T_f | B17: 11:33 | C17: 23.2 | D17: 13:08 | E17: 24.1
B18: Ora | D18: Ora | F18: Ora | H18: Ora | J18: Ora
A19: Okite | C19: 1 | E19: 2 | G19: 3 | I19: 4 (opzionale) | K19: 5 (opzionale)
A20: T circa 65 °C | B20: 11:31 | C20: 65 | D20: 11:53 | E20: 65 | F20: 12:52 | G20: 66
A21: T1 | B21: 11:36 | C21: 61 | D21: 11:57 | E21: 60.4 | F21: 12:53 | G21: 61.5
A22: m_a * | B22: 11:32 | C22: 200 | D22: 11:57 | E22: 205.1 | F22: 12:53 | G22: 202
A23: m1 | B23: 10:25 | C23: 100.8 | D23: 11:45 | E23: 100.8 | F23: 12:52 | G23: 100.8
A24: T_a | B24: 11:33 | C24: 23.6 | D24: 11:57 | E24: 24.4 | F24: 12:54 | G24: 24
A25: T_f | B25: 11:40 | C25: 26.8 | D25: 12:00 | E25: 27.4 | F25: 12:59 | G25: 27.2
B26: Ora | D26: Ora | F26: Ora | H26: Ora | J26: Ora
A27: Granito | C27: 1 | E27: 2 | I27: 4 (opzionale) | K27: 5 (opzionale)
A28: T circa 65 °C | B28: 11:44 | C28: 65 | D28: 13:09 | E28: 66
A29: T1 | B29: 11:47 | C29: 61.8 | D29: 13:10 | E29: 62
A30: m_a * | B30: 11:46 | C30: 203.5 | D30: 13:11 | E30: 201.8
A31: m1 | B31: 10:26 | C31: 112.9 | D31: 10:27 | E31: 112.9
A32: T_a | B32: 11:48 | C32: 25 | D32: 13:11 | E32: 24.6
A33: T_f | B33: 11:52 | C33: 28.4 | D33: 13:19 | E33: 28.1
A35: 0.3 Ghiaccio disciolto in acqua e calore latente
B36: Ora | C36: 1 | D36: Ora | E36: 2 | F36: Ora | G36: 3 | H36: Ora | I36: 4 (opzionale) | J36: Ora | K36: 5 (opzionale)
A37: m_a | B37: 12:08 | C37: 197.8 | D37: 12:25 | E37: 198.8 | F37: 12:36 | G37: 214.5 | H37: 12:47 | I37: 200.8
A38: T_a | B38: 12:14 | C38: 52 | D38: 12:26 | E38: 54 | F38: 12:37 | G38: 55.6 | H38: 12:47 | I38: 52
A39: m_g | B39: 12:16 | C39: 70 | D39: 12:28 | E39: 70.3 | F39: 12:38 | G39: 69.3 | H39: 12:48 | I39: 70.6
A40: T_f | B40: 12:19 | C40: 21.6 | D40: 12:30 | E40: 23 | F40: 12:42 | G40: 26 | H40: 12:52 | I40: 21.6
A42: 0.7 Operazioni per Misura Massa Equivalente del thermos (opzionale)
...

Sheet 0.2 Al
A1: =Raccolta!C4 -> 70 | B1: =Raccolta!E4 -> 64 | C1: =Raccolta!G4 -> 65 | D1: =Raccolta!I4 -> 66.8 | E1: =Raccolta!K4 -> 69
A2: =Raccolta!C5 -> 66 | B2: =Raccolta!E5 -> 62 | C2: =Raccolta!G5 -> 61.2 | D2: =Raccolta!I5 -> 63.8 | E2: =Raccolta!K5 -> 65.2
A3: =Raccolta!C6 -> 202 | B3: =Raccolta!E6 -> 201 | C3: =Raccolta!G6 -> 203 | D3: =Raccolta!I6 -> 202.5 | E3: =Raccolta!K6 -> 202
A4: =Raccolta!C7 -> 79.5 | B4: =Raccolta!E7 -> 79.5 | C4: =Raccolta!G7 -> 79.5 | D4: =Raccolta!I7 -> 79.5 | E4: =Raccolta!K7 -> 79.5
A5: =Raccolta!C8 -> 20 | B5: =Raccolta!E8 -> 23 | C5: =Raccolta!G8 -> 20.6 | D5: =Raccolta!I8 -> 23.2 | E5: =Raccolta!K8 -> 24.2
A6: =Raccolta!C9 -> 23.2 | B6: =Raccolta!E9 -> 25.6 | C6: =Raccolta!G9 -> 23.4 | D6: =Raccolta!I9 -> 26 | E6: =Raccolta!K9 -> 27

Sheet 0.2 Ottone
A1: =Raccolta!C12 -> 67 | B1: =Raccolta!E12 -> 66 | C1: =Raccolta!G12
A2: =Raccolta!C13 -> 64 | B2: =Raccolta!E13 -> 63.5 | C2: =Raccolta!G13 | D2: =Raccolta!I14 | E2: =Raccolta!K14
A3: =Raccolta!C14 -> 200.6 | B3: =Raccolta!E14 -> 202.4 | C3: =Raccolta!G14 | D3: =Raccolta!I16 | E3: =Raccolta!K16
A4: =Raccolta!C15 -> 195.3 | B4: =Raccolta!E15 -> 195.3 | C4: =Raccolta!G15 | D4: =Raccolta!I17 | E4: =Raccolta!K17
A5: =Raccolta!C16 -> 20 | B5: =Raccolta!E16 -> 21 | C5: =Raccolta!G16
A6: =Raccolta!C17 -> 23.2 | B6: =Raccolta!E17 -> 24.1 | C6: =Raccolta!G17

Sheet 0.2 Okite
A1: =Raccolta!C20 -> 65 | B1: =Raccolta!E20 -> 65 | C1: =Raccolta!G20 -> 66 | D1: =Raccolta!I20 | E1: =Raccolta!K20
A2: =Raccolta!C21 -> 61 | B2: =Raccolta!E21 -> 60.4 | C2: =Raccolta!G21 -> 61.5 | D2: =Raccolta!I22 | E2: =Raccolta!K22
A3: =Raccolta!C22 -> 200 | B3: =Raccolta!E22 -> 205.1 | C3: =Raccolta!G22 -> 202 | D3: =Raccolta!I24 | E3: =Raccolta!K24
A4: =Raccolta!C23 -> 100.8 | B4: =Raccolta!E23 -> 100.8 | C4: =Raccolta!G23 -> 100.8 | D4: =Raccolta!I25 | E4: =Raccolta!K25
A5: =Raccolta!C24 -> 23.6 | B5: =Raccolta!E24 -> 24.4 | C5: =Raccolta!G24 -> 24
A6: =Raccolta!C25 -> 26.8 | B6: =Raccolta!E25 -> 27.4 | C6: =Raccolta!G25 -> 27.2

Sheet 0.2 Granito
A1: =Raccolta!C28 -> 65 | B1: =Raccolta!E28 -> 66 | C1: =Raccolta!G28 | D1: =Raccolta!I28 | E1: =Raccolta!K28
A2: =Raccolta!C29 -> 61.8 | B2: =Raccolta!E29 -> 62 | C2: =Raccolta!G29 | D2: =Raccolta!I30 | E2: =Raccolta!K30
A3: =Raccolta!C30 -> 203.5 | B3: =Raccolta!E30 -> 201.8 | C3: =Raccolta!G30 | D3: =Raccolta!I32 | E3: =Raccolta!K32
A4: =Raccolta!C31 -> 112.9 | B4: =Raccolta!E31 -> 112.9 | C4: =Raccolta!G31 | D4: =Raccolta!I33 | E4: =Raccolta!K33
A5: =Raccolta!C32 -> 25 | B5: =Raccolta!E32 -> 24.6 | C5: =Raccolta!G32
A6: =Raccolta!C33 -> 28.4 | B6: =Raccolta!E33 -> 28.1 | C6: =Raccolta!G33

Sheet 0.3
A1: =Raccolta!C37 -> 197.8 | B1: =Raccolta!E37 -> 198.8 | C1: =Raccolta!G37 -> 214.5 | D1: =Raccolta!I37 -> 200.8
A2: =Raccolta!C38 -> 52 | B2: =Raccolta!E38 -> 54 | C2: =Raccolta!G38 -> 55.6 | D2: =Raccolta!I38 -> 52
A3: =Raccolta!C39 -> 70 | B3: =Raccolta!E39 -> 70.3 | C3: =Raccolta!G39 -> 69.3 | D3: =Raccolta!I39 -> 70.6
A4: =Raccolta!C40 -> 21.6 | B4: =Raccolta!E40 -> 23 | C4: =Raccolta!G40 -> 26 | D4: =Raccolta!I40 -> 21.6
A5: =Raccolta!C41

Sheet 0.7
A1: =Raccolta!C44 -> 100.5 | B1: =Raccolta!E44 | C1: =Raccolta!G44 | D1: =Raccolta!I44 | E1: =Raccolta!K44
A2: =Raccolta!C45 -> 4 | B2: =Raccolta!E45 | C2: =Raccolta!G45 | D2: =Raccolta!I45 | E2: =Raccolta!K45
A3: =Raccolta!C46 | B3: =Raccolta!E46 | C3: =Raccolta!G46 | D3: =Raccolta!I46 | E3: =Raccolta!K46
A4: =Raccolta!C48 -> 110.6 | B4: =Raccolta!E48 | C4: =Raccolta!G48 | D4: =Raccolta!I48 | E4: =Raccolta!K48
A5: =Raccolta!C49 -> 44 | B5: =Raccolta!E49 | C5: =Raccolta!G49 | D5: =Raccolta!I49 | E5: =Raccolta!K49
A6: =Raccolta!C50 | B6: =Raccolta!E50 | C6: =Raccolta!G50 | D6: =Raccolta!I50 | E6: =Raccolta!K50
A7: =Raccolta!C52 -> 23 | B7: =Raccolta!E52 | C7: =Raccolta!G52 | D7: =Raccolta!I52 | E7: =Raccolta!K52
